Traceback (most recent call last):
  File "/usr/lib/python2.7/site-packages/pudb/__init__.py", line 56, in runscript
    dbg._runscript(mainpyfile)
  File "/usr/lib/python2.7/site-packages/pudb/debugger.py", line 341, in _runscript
    self.run(statement, globals=globals_, locals=locals_)
  File "/usr/lib/python2.7/bdb.py", line 400, in run
    exec cmd in globals, locals
  File "<string>", line 1, in <module>
  File "sqlAnalyzer.py", line 749, in <module>
    main()
  File "sqlAnalyzer.py", line 113, in main
    plot_per_connection_downstream_ccdf(13, 111)
  File "sqlAnalyzer.py", line 553, in plot_per_connection_downstream_ccdf
    plt.xscale('log')
  File "/usr/lib/python2.7/site-packages/matplotlib/pyplot.py", line 1384, in xscale
    ax.set_xscale(*args, **kwargs)
  File "/usr/lib/python2.7/site-packages/matplotlib/axes.py", line 2583, in set_xscale
    self.autoscale_view(scaley=False)
  File "/usr/lib/python2.7/site-packages/matplotlib/axes.py", line 1948, in autoscale_view
    x0, x1 = xlocator.view_limits(x0, x1)
  File "/usr/lib/python2.7/site-packages/matplotlib/ticker.py", line 1485, in view_limits
    "Data has no positive values, and therefore can not be "
ValueError: Data has no positive values, and therefore can not be log-scaled.
